<?xml version="1.0" encoding="utf-8"?>
<!-- =================================================================================== -->
<!-- |    This document was autogenerated by xacro from manipulator4_meshed_test.xacro | -->
<!-- |    EDITING THIS FILE BY HAND IS NOT RECOMMENDED                                 | -->
<!-- =================================================================================== -->
<robot name="manipulator">
  <!--0.5624 height to start-->
  <material name="white">
    <color rgba="1 1 1 1"/>
  </material>
  <!-- <xacro:property name="MXVolume" value="0.000070668734375"/> -->
  <!-- <xacro:property name="Link1Volume" value="0.000231393781250"/> -->
  <!-- <xacro:property name="Link2Volume" value="0.000173506343750"/> -->
  <!-- MACROS -->
  <!-- LINKS -->
  <!-- the trans parameter present here is to toggle distance of current object with respect to previous adjacent object i.e. its parent-->
  <!-- <link name="base_link">
    <xacro:LinkInertial trans="0 0 0.5624" rpy="0 0 0" />
    <xacro:LinkVisual trans="0 0 0.5624" rpy="0 0 0" />
    <xacro:LinkCollision trans="0 0 0.5624" rpy="0 0 0" />
  </link> -->
  <link name="shoulder_pitch_motor">
    <inertial>
      <origin rpy="0 0 0 " xyz="0 0 0"/>
      <mass value="0.165"/>
      <inertia ixx="6.65123572902532E-05" ixy="-4.54345384616915E-11" ixz="-5.15255173621468E-12" iyy="5.68182433930847E-05" iyz="-6.73804871717713E-07" izz="3.74108886112339E-05"/>
    </inertial>
    <visual>
      <origin rpy="0 0 0 " xyz="0 0 0"/>
      <geometry>
        <mesh filename="package://arm_imitation/meshes/mx-64.stl" scale="0.001 0.001 0.001"/>
      </geometry>
      <material name="white"/>
    </visual>
    <collision>
      <origin rpy="0 0 0" xyz="0 0 0"/>
      <geometry>
        <mesh filename="package://arm_imitation/meshes/mx-64.stl" scale="0.001 0.001 0.001"/>
      </geometry>
    </collision>
  </link>
  <link name="shoulder_roll_motor">
    <inertial>
      <origin rpy="0 0 0 " xyz="0 0 0.0481"/>
      <mass value="0.165"/>
      <inertia ixx="6.65123572902532E-05" ixy="-4.54345384616915E-11" ixz="-5.15255173621468E-12" iyy="5.68182433930847E-05" iyz="-6.73804871717713E-07" izz="3.74108886112339E-05"/>
    </inertial>
    <visual>
      <origin rpy="0 0 0 " xyz="0 0 0.0481"/>
      <geometry>
        <mesh filename="package://arm_imitation/meshes/mx-64.stl" scale="0.001 0.001 0.001"/>
      </geometry>
      <material name="white"/>
    </visual>
    <collision>
      <origin rpy="0 0 0" xyz="0 0 0.0481"/>
      <geometry>
        <mesh filename="package://arm_imitation/meshes/mx-64.stl" scale="0.001 0.001 0.001"/>
      </geometry>
    </collision>
  </link>
  <link name="shoulder_yaw_motor">
    <inertial>
      <origin rpy="0 0 0" xyz="0 0 0"/>
      <mass value="0.165"/>
      <inertia ixx="6.65123572902532E-05" ixy="-4.54345384616915E-11" ixz="-5.15255173621468E-12" iyy="5.68182433930847E-05" iyz="-6.73804871717713E-07" izz="3.74108886112339E-05"/>
    </inertial>
    <visual>
      <origin rpy="0.0 0.0 0" xyz="0 0 0"/>
      <geometry>
        <mesh filename="package://arm_imitation/meshes/mx-64.stl" scale="0.001 0.001 0.001"/>
      </geometry>
      <material name="white"/>
    </visual>
    <collision>
      <origin rpy="0 0 0" xyz="0 0 0"/>
      <geometry>
        <mesh filename="package://arm_imitation/meshes/mx-64.stl" scale="0.001 0.001 0.001"/>
      </geometry>
    </collision>
  </link>
  <link name="link_1">
    <inertial>
      <origin rpy="0 0 0" xyz="0 0 0"/>
      <mass value="0.265"/>
      <inertia ixx="0.000608361426086" ixy="7.77278472820011E-11" ixz="2.27900791642819E-11" iyy="6.93532385616405E-05" iyz="7.00240819830694E-08" izz="0.000605959073862"/>
    </inertial>
    <visual>
      <origin rpy="0.0 0.0 0" xyz="0 0 0"/>
      <geometry>
        <mesh filename="package://arm_imitation/meshes/link1.stl" scale="0.001 0.001 0.001"/>
      </geometry>
      <material name="white"/>
    </visual>
    <collision>
      <origin rpy="0 0 0" xyz="0 0 0"/>
      <geometry>
        <mesh filename="package://arm_imitation/meshes/link1.stl" scale="0.001 0.001 0.001"/>
      </geometry>
    </collision>
  </link>
  <link name="link_2">
    <inertial>
      <origin rpy="0 0 0" xyz="0 0 0"/>
      <mass value="0.265"/>
      <inertia ixx="0.000353833500666" ixy="-9.91181241544464E-11" ixz="2.17719851471636E-11" iyy="7.68817830247818E-05" iyz="-6.50168183616403E-07" izz="0.000363033715751"/>
    </inertial>
    <visual>
      <origin rpy="0.0 0.0 0" xyz="0 0 0"/>
      <geometry>
        <mesh filename="package://arm_imitation/meshes/link2.stl" scale="0.001 0.001 0.001"/>
      </geometry>
      <material name="white"/>
    </visual>
    <collision>
      <origin rpy="0 0 0" xyz="0 0 0"/>
      <geometry>
        <mesh filename="package://arm_imitation/meshes/link2.stl" scale="0.001 0.001 0.001"/>
      </geometry>
    </collision>
  </link>
  <joint name="shoulder_pitch" type="revolute">
    <origin rpy="-1.57 -1.57 0" xyz="0 0.0205 0"/>
    <parent link="shoulder_pitch_motor"/>
    <child link="shoulder_roll_motor"/>
    <axis xyz="0 0 1"/>
    <limit effort="30" lower="-3.14" upper="3.14" velocity="1.0"/>
  </joint>
  <joint name="shoulder_roll" type="revolute">
    <origin rpy="1.57 1.57 3.14" xyz="0 0.0686 0.0481"/>
    <parent link="shoulder_roll_motor"/>
    <child link="shoulder_yaw_motor"/>
    <axis xyz="0 0 -1"/>
    <limit effort="30" lower="-3.14" upper="3.14" velocity="1.0"/>
  </joint>
  <joint name="shoulder_yaw" type="revolute">
    <origin rpy="1.57 0 -1.57" xyz="0 0 0"/>
    <parent link="shoulder_yaw_motor"/>
    <child link="link_1"/>
    <axis xyz="1 0 0"/>
    <limit effort="30" lower="-1.57" upper="1.57" velocity="1.0"/>
  </joint>
  <joint name="elbow_pitch" type="revolute">
    <origin rpy="0 -1.57 0" xyz="0 0.1801 0"/>
    <parent link="link_1"/>
    <child link="link_2"/>
    <axis xyz="1 0 0"/>
    <limit effort="30" lower="-1.57" upper="1.57" velocity="1.0"/>
  </joint>
  <!-- <xacro:RevJoint id="shoulder_yaw" trans="0 ${MXLengthAxisLong} 0" rpy="-1.57 1.57 1.57" parent="shoulder_pitch_motor" child="link_1" axis="-1 0 0" l="-1.57" u="1.57" v="1.0"/> -->
  <!-- <xacro:RevJoint id="elbow_pitch" trans="0 -${MXBracketLength + LinkLength + MXLengthAxisLong} 0" rpy="0 0 0" parent="link_1" child="link_2" axis="0 0 1" l="-1.57" u="1.57" v="1.0"/> -->
  <!-- axis="1 0 0" l="-1.57" u="1.57" v="1.0" -->
  <!-- <xacro:FxdJoint id="biceps_start" trans="0 0 ${MXBracketLength}" rpy="0 0 3.14" parent="shoulder_bracket" child="biscep"/>
  <xacro:FxdJoint id="biceps_end" trans="0 0 ${LinkLength}" rpy="1.57 0 1.57" parent="biscep" child="elbow_motor"/>
  <xacro:RevJoint id="elbow_pitch" trans="0 ${MXLengthAxisLong} 0" rpy="0 1.57 1.57" parent="elbow_motor" child="elbow_bracket" axis="1 0 0" l="-1.57" u="1.57" v="1.0"/>
  <xacro:FxdJoint id="forearm_start" trans="0 0 ${MXBracketLength}" rpy="0 0 3.14" parent="elbow_bracket" child="forearm"/>
  <xacro:FxdJoint id="forearm_end" trans="0 0 ${LinkLength}" rpy="1.57 0 1.57" parent="forearm" child="wrist_bracket"/> -->
</robot>
