<?xml version="1.0" encoding="utf-8"?>
<!-- =================================================================================== -->
<!-- |    This document was autogenerated by xacro from manipulator.xacro              | -->
<!-- |    EDITING THIS FILE BY HAND IS NOT RECOMMENDED                                 | -->
<!-- =================================================================================== -->
<robot name="mobile_manipulator">
  <material name="white">
    <color rgba="1 1 1 1"/>
  </material>
  <!-- MACROS -->
  <!-- Macros of the AXBracket -->
  <!-- LINKS -->
  <link name="shoulder_yaw_motor">
    <inertial>
      <origin rpy="0 0 0 " xyz="0 0 0"/>
      <mass value="0.140"/>
      <inertia ixx="0.000050799110" ixy="0.0" ixz="0.0" iyy="0.00002857215" iyz="0.00000051457" izz="0.000043394"/>
    </inertial>
    <visual>
      <origin rpy="0 0 0 " xyz="0 0.188 0.2349"/>
      <geometry>
        <mesh filename="package://mobile_manipulator/meshes/dynamixel_x64series.stl" scale="0.001 0.001 0.001"/>
      </geometry>
      <material name="white"/>
    </visual>
    <collision>
      <origin rpy="0 0 0" xyz="0 0.188 0.2349"/>
      <geometry>
        <box size="0.041 0.0402 0.0611"/>
      </geometry>
    </collision>
  </link>
  <link name="shoulder_bracket">
    <inertial>
      <origin rpy="0 0 0 " xyz="0 0 0.025"/>
      <mass value="0.00712"/>
      <inertia ixx="0.00000174511" ixy="0.0" ixz="0.0" iyy="0.00000379922" iyz="0.0" izz="0.00000357521"/>
    </inertial>
    <visual>
      <origin rpy="0 0 0 " xyz="0 0 0"/>
      <geometry>
        <mesh filename="package://mobile_manipulator/meshes/FR05-H101K.stl" scale="0.001 0.001 0.001"/>
      </geometry>
      <material name="white"/>
    </visual>
    <collision>
      <origin rpy="0 0 0 " xyz="0 0 0"/>
      <geometry>
        <mesh filename="package://mobile_manipulator/meshes/FR05-H101K.stl" scale="0.001 0.001 0.001"/>
      </geometry>
    </collision>
  </link>
  <link name="shoulder_pitch_motor">
    <inertial>
      <origin rpy="0 0 0" xyz="0 0 0"/>
      <mass value="0.140"/>
      <inertia ixx="0.000050799110" ixy="0.0" ixz="0.0" iyy="0.00002857215" iyz="0.00000051457" izz="0.000043394"/>
    </inertial>
    <visual>
      <origin rpy="0.0 0.0 0" xyz="0 0 0"/>
      <geometry>
        <mesh filename="package://mobile_manipulator/meshes/dynamixel_x64series.stl" scale="0.001 0.001 0.001"/>
      </geometry>
      <material name="white"/>
    </visual>
    <collision>
      <origin rpy="0 0 0" xyz="0 0 0"/>
      <geometry>
        <box size="0.041 0.0602 0.1480"/>
      </geometry>
    </collision>
  </link>
  <!-- <link name="biscep">
    <xacro:LinkInertial trans="${0.051+(length/2)} 0 0" rpy="0 1.57 0" />
    <xacro:LinkVisual trans="${0.051+(length/2)} 0 0" rpy="0 1.57 0" />
    <xacro:LinkCollision trans="${0.051+(length/2)} 0 0" rpy="0 1.57 0" />
  </link> 

  <link name="elbow_bracket">
    <xacro:BracketInertial trans="${0.052+length} 0 0" rpy="0 -1.57 0"/>
    <xacro:BracketVisual trans="${0.052+length} 0 0" rpy="0 -1.57 0"/>
    <xacro:BracketCollision trans="${0.052+length} 0 0" rpy="0 -1.57 0"/>
  </link>   

  <link name="elbow_motor">
    <xacro:MXInertial trans="0 0 0" rpy="0 0 1.57"/>  
    <xacro:MXVisual trans="0 0 0" rpy="0 0 1.57"/>
    <xacro:MXCollision trans="0  0 0" rpy="0 0 1.57"/>
  </link>

  <link name="forearm">
    <xacro:LinkInertial trans="${0.052+(length/2)} 0 0" rpy="0 1.57 0" />
    <xacro:LinkVisual trans="${0.052+(length/2)} 0 0" rpy="0 1.57 0" />
    <xacro:LinkCollision trans="${0.052+(length/2)} 0 0" rpy="0 1.57 0" />
  </link> 
  
  <link name="wrist_bracket">
    <xacro:AxBracketInertial trans="${0.052+length+0.054} 0 0" rpy="0 0 -1.57"/>
    <xacro:AxBracketVisual trans="${0.052+length+0.054} 0 0" rpy="0 0 -1.57"/>
    <xacro:AxBracketCollision trans="${0.052+length+0.054} 0 0" rpy="0 0 -1.57"/>
  </link> -->
  <!-- JOINTS -->
  <joint name="shoulder_yaw" type="revolute">
    <origin rpy="0 3.14 3.14" xyz="0 0.188 0.2577"/>
    <parent link="shoulder_yaw_motor"/>
    <child link="shoulder_bracket"/>
    <axis xyz="0 0 1"/>
    <limit effort="30" lower="-3.14" upper="3.14" velocity="1.0"/>
  </joint>
  <joint name="shoulder_pitch" type="revolute">
    <origin rpy="0 -1.57 0" xyz="0 0 -0.035"/>
    <parent link="shoulder_bracket"/>
    <child link="shoulder_pitch_motor"/>
    <axis xyz="0 0 1"/>
    <limit effort="30" lower="-3.14" upper="0" velocity="1.0"/>
  </joint>
  <!-- <xacro:FxdJoint id="s1_l2" trans="0 0 0" rpy="0 0 0" parent="shoulder_pitch_motor" child="biscep"/>
  <xacro:FxdJoint id="l2_l2B" trans="0 0 0" rpy="0 0 0" parent="biscep" child="elbow_bracket"/>
  <xacro:Revjoint id="elbow" trans="${0.052 + (length) + 0.038} 0 0" rpy="0 0 0" parent="elbow_bracket" child="elbow_motor" axis="0 0 1" l="-1.9262" u="1.934" v="1.0"/>
  <xacro:FxdJoint id="e_l3" trans="0 0 0" rpy="0 0 0" parent="elbow_motor" child="forearm"/>
  <xacro:FxdJoint id="l3_l3B" trans="0 0 0" rpy="0 0 0" parent="forearm" child="wrist_bracket"/> -->
</robot>
