<?xml version="1.0" encoding="utf-8"?>
<!-- =================================================================================== -->
<!-- |    This document was autogenerated by xacro from manipulator4_gripper.xacro     | -->
<!-- |    EDITING THIS FILE BY HAND IS NOT RECOMMENDED                                 | -->
<!-- =================================================================================== -->
<robot name="manipulator">
  <!--0.5624 height to start-->
  <material name="white">
    <color rgba="1 1 1 1"/>
  </material>
  <!-- <xacro:property name="MXVolume" value="0.000070668734375"/> -->
  <!-- <xacro:property name="Link1Volume" value="0.000231393781250"/> -->
  <!-- <xacro:property name="Link2Volume" value="0.000173506343750"/> -->
  <!-- MACROS -->
  <!-- LINKS -->
  <link name="shoulder_pitch_motor">
    <inertial>
      <origin rpy="0 0 0 " xyz="0 0 0"/>
      <mass value="0.165"/>
      <inertia ixx="3.85605E-05" ixy="3.5409E-07" ixz="7.7913E-07" iyy="6.21555E-05" iyz="2.7126E-07" izz="5.51265E-05"/>
    </inertial>
    <visual>
      <origin rpy="0 0 0 " xyz="0 0 0"/>
      <geometry>
        <mesh filename="package://arm_imitation/meshes/mx-64.stl" scale="0.001 0.001 0.001"/>
      </geometry>
      <material name="white"/>
    </visual>
    <collision>
      <origin rpy="0 0 0" xyz="0 0 0"/>
      <geometry>
        <mesh filename="package://arm_imitation/meshes/mx-64.stl" scale="0.001 0.001 0.001"/>
      </geometry>
    </collision>
  </link>
  <link name="shoulder_roll_motor">
    <inertial>
      <origin rpy="0 0 0 " xyz="0 0 0.0481"/>
      <mass value="0.165"/>
      <inertia ixx="3.85605E-05" ixy="3.5409E-07" ixz="7.7913E-07" iyy="6.21555E-05" iyz="2.7126E-07" izz="5.51265E-05"/>
    </inertial>
    <visual>
      <origin rpy="0 0 0 " xyz="0 0 0.0481"/>
      <geometry>
        <mesh filename="package://arm_imitation/meshes/mx-64.stl" scale="0.001 0.001 0.001"/>
      </geometry>
      <material name="white"/>
    </visual>
    <collision>
      <origin rpy="0 0 0" xyz="0 0 0.0481"/>
      <geometry>
        <mesh filename="package://arm_imitation/meshes/mx-64.stl" scale="0.001 0.001 0.001"/>
      </geometry>
    </collision>
  </link>
  <link name="shoulder_yaw_motor">
    <inertial>
      <origin rpy="0 0 0" xyz="0 0 0"/>
      <mass value="0.165"/>
      <inertia ixx="3.85605E-05" ixy="3.5409E-07" ixz="7.7913E-07" iyy="6.21555E-05" iyz="2.7126E-07" izz="5.51265E-05"/>
    </inertial>
    <visual>
      <origin rpy="0 0 0" xyz="0 0 0"/>
      <geometry>
        <mesh filename="package://arm_imitation/meshes/mx-64.stl" scale="0.001 0.001 0.001"/>
      </geometry>
      <material name="white"/>
    </visual>
    <collision>
      <origin rpy="0 0 0" xyz="0 0 0"/>
      <geometry>
        <mesh filename="package://arm_imitation/meshes/mx-64.stl" scale="0.001 0.001 0.001"/>
      </geometry>
    </collision>
  </link>
  <link name="link_1">
    <inertial>
      <origin rpy="0 0 0" xyz="0 0 0"/>
      <mass value="0.185"/>
      <inertia ixx="4.8914E-05" ixy="3.46135E-07" ixz="-2.24405E-06" iyy="9.83275E-05" iyz="5.71095E-07" izz="9.4054E-05"/>
    </inertial>
    <visual>
      <origin rpy="0 0 0" xyz="0 0 0"/>
      <geometry>
        <mesh filename="package://arm_imitation/meshes/link3.stl" scale="0.001 0.001 0.001"/>
      </geometry>
      <material name="white"/>
    </visual>
    <collision>
      <origin rpy="0 0 0" xyz="0 0 0"/>
      <geometry>
        <mesh filename="package://arm_imitation/meshes/link3.stl" scale="0.001 0.001 0.001"/>
      </geometry>
    </collision>
  </link>
  <link name="link_2">
    <inertial>
      <origin rpy="0 0 0" xyz="0 0 0"/>
      <mass value="0.2651"/>
      <inertia ixx="0.00021581791" ixy="-4.474888E-05" ixz="-0.00015723081" iyy="0.0009819304" iyz="-3.653078E-05" izz="0.0010320343"/>
    </inertial>
    <visual>
      <origin rpy="0 0 0" xyz="0 0 0"/>
      <geometry>
        <mesh filename="package://arm_imitation/meshes/link4.stl" scale="0.001 0.001 0.001"/>
      </geometry>
      <material name="white"/>
    </visual>
    <collision>
      <origin rpy="0 0 0" xyz="0 0 0"/>
      <geometry>
        <mesh filename="package://arm_imitation/meshes/link4.stl" scale="0.001 0.001 0.001"/>
      </geometry>
    </collision>
  </link>
  <!-- JOINTS -->
  <!-- the trans parameter present here is to toggle distance of current object with respect to next adjacent object i.e. its child-->
  <!-- <xacro:RevJoint id="shoulder_pitch" trans="0 ${MXDepth/2} 0" rpy="-1.57 -1.57 0" parent="shoulder_pitch_motor" child="shoulder_roll_motor" axis="0 0 1" l="-3.14" u="3.14" v="1.0"/>
  <xacro:RevJoint id="shoulder_roll" trans="0 ${MXLengthAxisLong + MXDepth/2} ${MXLengthAxisLong}" rpy="1.57 1.57 3.14" parent="shoulder_roll_motor" child="shoulder_yaw_motor" axis="0 0 -1" l="-3.14" u="3.14" v="1.0"/>
  <xacro:RevJoint id="shoulder_yaw" trans="0 0 0" rpy="1.57 0 -1.57" parent="shoulder_yaw_motor" child="link_1" axis="1 0 0" l="-1.57" u="1.57" v="1.0"/>
  <xacro:RevJoint id="elbow_pitch" trans="0 ${MXBracketLength + LinkLength + MXLengthAxisLong} 0" rpy="0 -1.57 0" parent="link_1" child="link_2" axis="1 0 0" l="-1.57" u="1.57" v="1.0"/> -->
  <joint name="shoulder_pitch" type="revolute">
    <origin rpy="-1.57 -1.57 0" xyz="0 0.0205 0"/>
    <parent link="shoulder_pitch_motor"/>
    <child link="shoulder_roll_motor"/>
    <axis xyz="0 0 -1"/>
    <limit effort="30" lower="-3.14" upper="3.14" velocity="6.28"/>
  </joint>
  <joint name="shoulder_roll" type="revolute">
    <origin rpy="1.57 -1.57 3.14" xyz="0 0.0686 0.0481"/>
    <parent link="shoulder_roll_motor"/>
    <child link="shoulder_yaw_motor"/>
    <axis xyz="0 0 1"/>
    <limit effort="30" lower="-3.14" upper="3.14" velocity="6.28"/>
  </joint>
  <joint name="shoulder_yaw" type="revolute">
    <origin rpy="1.57 0 1.57" xyz="0 0 0"/>
    <parent link="shoulder_yaw_motor"/>
    <child link="link_1"/>
    <axis xyz="1 0 0"/>
    <limit effort="30" lower="-1.57" upper="1.57" velocity="6.28"/>
  </joint>
  <joint name="elbow_pitch" type="revolute">
    <origin rpy="0 1.57 0" xyz="0 0.0841 0"/>
    <parent link="link_1"/>
    <child link="link_2"/>
    <axis xyz="1 0 0"/>
    <limit effort="30" lower="-1.57" upper="1.57" velocity="6.28"/>
  </joint>
</robot>
