<?xml version="1.0" encoding="utf-8"?>
<!-- =================================================================================== -->
<!-- |    This document was autogenerated by xacro from manipulator4_meshed.xacro      | -->
<!-- |    EDITING THIS FILE BY HAND IS NOT RECOMMENDED                                 | -->
<!-- =================================================================================== -->
<robot name="manipulator">
  <!--0.5624 height to start-->
  <material name="white">
    <color rgba="1 1 1 1"/>
  </material>
  <!-- MACROS -->
  <!-- LINKS -->
  <!-- the trans parameter present here is to toggle distance of current object with respect to previous adjacent object i.e. its parent-->
  <link name="base_link">
    <inertial>
      <origin rpy="0 0 0" xyz="0 0 0.5624"/>
      <mass value="0.00048"/>
      <inertia ixx="0.000050799110" ixy="0.0" ixz="0.0" iyy="0.00002857215" iyz="0.00000051457" izz="0.000043394"/>
    </inertial>
    <visual>
      <origin rpy="0 0 0" xyz="0 0 0.5624"/>
      <geometry>
        <box size="0.04 0.04 0.096"/>
      </geometry>
      <material name="white"/>
    </visual>
    <collision>
      <origin rpy="0 0 0" xyz="0 0 0.5624"/>
      <geometry>
        <box size="0.04 0.04 0.096"/>
      </geometry>
    </collision>
  </link>
  <link name="shoulder_yaw_motor">
    <inertial>
      <origin rpy="0 0 0 " xyz="0 0 0.0205"/>
      <mass value="0.140"/>
      <inertia ixx="0.000050799110" ixy="0.0" ixz="0.0" iyy="0.00002857215" iyz="0.00000051457" izz="0.000043394"/>
    </inertial>
    <visual>
      <origin rpy="0 0 0 " xyz="0 0 0.0205"/>
      <geometry>
        <mesh filename="package://mobile_manipulator/meshes/dynamixel_x64series.stl" scale="0.001 0.001 0.001"/>
      </geometry>
      <material name="white"/>
    </visual>
    <collision>
      <origin rpy="0 0 0" xyz="0 0 0.0205"/>
      <geometry>
        <mesh filename="package://mobile_manipulator/meshes/dynamixel_x64series.stl" scale="0.001 0.001 0.001"/>
      </geometry>
    </collision>
  </link>
  <link name="shoulder_roll_motor">
    <inertial>
      <origin rpy="0 0 0 " xyz="0 0.0481 0.0004"/>
      <mass value="0.140"/>
      <inertia ixx="0.000050799110" ixy="0.0" ixz="0.0" iyy="0.00002857215" iyz="0.00000051457" izz="0.000043394"/>
    </inertial>
    <visual>
      <origin rpy="0 0 0 " xyz="0 0.0481 0.0004"/>
      <geometry>
        <mesh filename="package://mobile_manipulator/meshes/dynamixel_x64series.stl" scale="0.001 0.001 0.001"/>
      </geometry>
      <material name="white"/>
    </visual>
    <collision>
      <origin rpy="0 0 0" xyz="0 0.0481 0.0004"/>
      <geometry>
        <mesh filename="package://mobile_manipulator/meshes/dynamixel_x64series.stl" scale="0.001 0.001 0.001"/>
      </geometry>
    </collision>
  </link>
  <link name="shoulder_pitch_motor">
    <inertial>
      <origin rpy="0 0 0" xyz="0 0.0481 0"/>
      <mass value="0.140"/>
      <inertia ixx="0.000050799110" ixy="0.0" ixz="0.0" iyy="0.00002857215" iyz="0.00000051457" izz="0.000043394"/>
    </inertial>
    <visual>
      <origin rpy="0.0 0.0 0" xyz="0 0.0481 0"/>
      <geometry>
        <mesh filename="package://mobile_manipulator/meshes/dynamixel_x64series.stl" scale="0.001 0.001 0.001"/>
      </geometry>
      <material name="white"/>
    </visual>
    <collision>
      <origin rpy="0 0 0" xyz="0 0.0481 0"/>
      <geometry>
        <mesh filename="package://mobile_manipulator/meshes/dynamixel_x64series.stl" scale="0.001 0.001 0.001"/>
      </geometry>
    </collision>
  </link>
  <link name="link_1">
    <inertial>
      <origin rpy="0 0 0" xyz="0 0 0"/>
      <mass value="0.265"/>
      <inertia ixx="0.000050799110" ixy="0.0" ixz="0.0" iyy="0.00002857215" iyz="0.00000051457" izz="0.000043394"/>
    </inertial>
    <visual>
      <origin rpy="0.0 0.0 0" xyz="0 0 0"/>
      <geometry>
        <mesh filename="package://arm_imitation/meshes/link1.stl" scale="1 1 1"/>
      </geometry>
      <material name="white"/>
    </visual>
    <collision>
      <origin rpy="0 0 0" xyz="0 0 0"/>
      <geometry>
        <mesh filename="package://arm_imitation/meshes/link1.stl" scale="1 1 1"/>
      </geometry>
    </collision>
  </link>
  <link name="link_2">
    <inertial>
      <origin rpy="0 0 0" xyz="0 0 0"/>
      <mass value="0.265"/>
      <inertia ixx="0.000050799110" ixy="0.0" ixz="0.0" iyy="0.00002857215" iyz="0.00000051457" izz="0.000043394"/>
    </inertial>
    <visual>
      <origin rpy="0.0 0.0 0" xyz="0 0 0"/>
      <geometry>
        <mesh filename="package://arm_imitation/meshes/link2.stl" scale="1 1 1"/>
      </geometry>
      <material name="white"/>
    </visual>
    <collision>
      <origin rpy="0 0 0" xyz="0 0 0"/>
      <geometry>
        <mesh filename="package://arm_imitation/meshes/link2.stl" scale="1 1 1"/>
      </geometry>
    </collision>
  </link>
  <joint name="base_joint" type="fixed">
    <origin rpy="1.57 0 3.14" xyz="0 0.02 0.5624"/>
    <parent link="base_link"/>
    <child link="shoulder_yaw_motor"/>
  </joint>
  <joint name="shoulder_pitch" type="revolute">
    <origin rpy="1.57 0 0" xyz="0 0 0.041"/>
    <parent link="shoulder_yaw_motor"/>
    <child link="shoulder_roll_motor"/>
    <axis xyz="0 1 0"/>
    <limit effort="30" lower="-3.14" upper="3.14" velocity="1.0"/>
  </joint>
  <joint name="shoulder_roll" type="revolute">
    <origin rpy="1.57 0 1.57" xyz="0 0.0481 0.0205"/>
    <parent link="shoulder_roll_motor"/>
    <child link="shoulder_pitch_motor"/>
    <axis xyz="0 1 0"/>
    <limit effort="30" lower="-3.14" upper="3.14" velocity="1.0"/>
  </joint>
  <joint name="shoulder_yaw" type="revolute">
    <origin rpy="-1.57 1.57 1.57" xyz="0 0.0481 0"/>
    <parent link="shoulder_pitch_motor"/>
    <child link="link_1"/>
    <axis xyz="-1 0 0"/>
    <limit effort="30" lower="-1.57" upper="1.57" velocity="1.0"/>
  </joint>
  <joint name="elbow_pitch" type="revolute">
    <origin rpy="0 0 0" xyz="0 -0.1801 0"/>
    <parent link="link_1"/>
    <child link="link_2"/>
    <axis xyz="0 0 1"/>
    <limit effort="30" lower="-1.57" upper="1.57" velocity="1.0"/>
  </joint>
  <!-- axis="1 0 0" l="-1.57" u="1.57" v="1.0" -->
  <!-- <xacro:FxdJoint id="biceps_start" trans="0 0 ${MXBracketLength}" rpy="0 0 3.14" parent="shoulder_bracket" child="biscep"/>
  <xacro:FxdJoint id="biceps_end" trans="0 0 ${LinkLength}" rpy="1.57 0 1.57" parent="biscep" child="elbow_motor"/>
  <xacro:RevJoint id="elbow_pitch" trans="0 ${MXLengthAxisLong} 0" rpy="0 1.57 1.57" parent="elbow_motor" child="elbow_bracket" axis="1 0 0" l="-1.57" u="1.57" v="1.0"/>
  <xacro:FxdJoint id="forearm_start" trans="0 0 ${MXBracketLength}" rpy="0 0 3.14" parent="elbow_bracket" child="forearm"/>
  <xacro:FxdJoint id="forearm_end" trans="0 0 ${LinkLength}" rpy="1.57 0 1.57" parent="forearm" child="wrist_bracket"/> -->
</robot>
