<?xml version="1.0" encoding="utf-8"?>
<!-- =================================================================================== -->
<!-- |    This document was autogenerated by xacro from manipulator3.xacro             | -->
<!-- |    EDITING THIS FILE BY HAND IS NOT RECOMMENDED                                 | -->
<!-- =================================================================================== -->
<robot name="mobile_manipulator">
  <material name="white">
    <color rgba="1 1 1 1"/>
  </material>
  <!-- MACROS -->
  <!-- LINKS -->
  <link name="base_link">
    <inertial>
      <origin rpy="0 0 0" xyz="0 0 0"/>
      <mass value="0.00048"/>
      <inertia ixx="0.000050799110" ixy="0.0" ixz="0.0" iyy="0.00002857215" iyz="0.00000051457" izz="0.000043394"/>
    </inertial>
    <visual>
      <origin rpy="0 0 0" xyz="0 0 0"/>
      <geometry>
        <box size="0.04 0.04 0.096"/>
      </geometry>
      <material name="white"/>
    </visual>
    <collision>
      <origin rpy="0 0 0" xyz="0 0 0"/>
      <geometry>
        <box size="0.04 0.04 0.096"/>
      </geometry>
    </collision>
  </link>
  <link name="shoulder_yaw_motor">
    <inertial>
      <origin rpy="0 0 0 " xyz="0 0 0.0205"/>
      <mass value="0.140"/>
      <inertia ixx="0.000050799110" ixy="0.0" ixz="0.0" iyy="0.00002857215" iyz="0.00000051457" izz="0.000043394"/>
    </inertial>
    <visual>
      <origin rpy="0 0 0 " xyz="0 0 0.0205"/>
      <geometry>
        <mesh filename="package://mobile_manipulator/meshes/dynamixel_x64series.stl" scale="0.001 0.001 0.001"/>
      </geometry>
      <material name="white"/>
    </visual>
    <collision>
      <origin rpy="0 0 0" xyz="0 0 0.0205"/>
      <geometry>
        <mesh filename="package://mobile_manipulator/meshes/dynamixel_x64series.stl" scale="0.001 0.001 0.001"/>
      </geometry>
    </collision>
  </link>
  <link name="shoulder_pitch_motor">
    <inertial>
      <origin rpy="0 0 0" xyz="0 0.0481 0"/>
      <mass value="0.140"/>
      <inertia ixx="0.000050799110" ixy="0.0" ixz="0.0" iyy="0.00002857215" iyz="0.00000051457" izz="0.000043394"/>
    </inertial>
    <visual>
      <origin rpy="0.0 0.0 0" xyz="0 0.0481 0"/>
      <geometry>
        <mesh filename="package://mobile_manipulator/meshes/dynamixel_x64series.stl" scale="0.001 0.001 0.001"/>
      </geometry>
      <material name="white"/>
    </visual>
    <collision>
      <origin rpy="0 0 0" xyz="0 0.0481 0"/>
      <geometry>
        <mesh filename="package://mobile_manipulator/meshes/dynamixel_x64series.stl" scale="0.001 0.001 0.001"/>
      </geometry>
    </collision>
  </link>
  <link name="shoulder_bracket">
    <inertial>
      <origin rpy="0 0 0 " xyz="0 0 0.036"/>
      <mass value="0.00712"/>
      <inertia ixx="0.00000174511" ixy="0.0" ixz="0.0" iyy="0.00000379922" iyz="0.0" izz="0.00000357521"/>
    </inertial>
    <visual>
      <origin rpy="0 0 0 " xyz="0 0 0.036"/>
      <geometry>
        <mesh filename="package://mobile_manipulator/meshes/FR05-H101K.stl" scale="0.001 0.001 0.001"/>
      </geometry>
      <material name="white"/>
    </visual>
    <collision>
      <origin rpy="0 0 0 " xyz="0 0 0.036"/>
      <geometry>
        <mesh filename="package://mobile_manipulator/meshes/FR05-H101K.stl" scale="0.001 0.001 0.001"/>
      </geometry>
    </collision>
  </link>
  <link name="biscep">
    <inertial>
      <origin rpy="0 0 0" xyz="0 0 0.048"/>
      <mass value="0.00048"/>
      <inertia ixx="0.000050799110" ixy="0.0" ixz="0.0" iyy="0.00002857215" iyz="0.00000051457" izz="0.000043394"/>
    </inertial>
    <visual>
      <origin rpy="0 0 0" xyz="0 0 0.048"/>
      <geometry>
        <box size="0.04 0.04 0.096"/>
      </geometry>
      <material name="white"/>
    </visual>
    <collision>
      <origin rpy="0 0 0" xyz="0 0 0.048"/>
      <geometry>
        <box size="0.04 0.04 0.096"/>
      </geometry>
    </collision>
  </link>
  <link name="elbow_motor">
    <inertial>
      <origin rpy="0 0 0" xyz="0 0.0481 0"/>
      <mass value="0.140"/>
      <inertia ixx="0.000050799110" ixy="0.0" ixz="0.0" iyy="0.00002857215" iyz="0.00000051457" izz="0.000043394"/>
    </inertial>
    <visual>
      <origin rpy="0 0 0" xyz="0 0.0481 0"/>
      <geometry>
        <mesh filename="package://mobile_manipulator/meshes/dynamixel_x64series.stl" scale="0.001 0.001 0.001"/>
      </geometry>
      <material name="white"/>
    </visual>
    <collision>
      <origin rpy="0 0 0" xyz="0 0.0481 0"/>
      <geometry>
        <mesh filename="package://mobile_manipulator/meshes/dynamixel_x64series.stl" scale="0.001 0.001 0.001"/>
      </geometry>
    </collision>
  </link>
  <link name="elbow_bracket">
    <inertial>
      <origin rpy="0 0 0" xyz="0 0 0.036"/>
      <mass value="0.00712"/>
      <inertia ixx="0.00000174511" ixy="0.0" ixz="0.0" iyy="0.00000379922" iyz="0.0" izz="0.00000357521"/>
    </inertial>
    <visual>
      <origin rpy="0 0 0" xyz="0 0 0.036"/>
      <geometry>
        <mesh filename="package://mobile_manipulator/meshes/FR05-H101K.stl" scale="0.001 0.001 0.001"/>
      </geometry>
      <material name="white"/>
    </visual>
    <collision>
      <origin rpy="0 0 0" xyz="0 0 0.036"/>
      <geometry>
        <mesh filename="package://mobile_manipulator/meshes/FR05-H101K.stl" scale="0.001 0.001 0.001"/>
      </geometry>
    </collision>
  </link>
  <link name="forearm">
    <inertial>
      <origin rpy="0 0 0" xyz="0 0 0.048"/>
      <mass value="0.00048"/>
      <inertia ixx="0.000050799110" ixy="0.0" ixz="0.0" iyy="0.00002857215" iyz="0.00000051457" izz="0.000043394"/>
    </inertial>
    <visual>
      <origin rpy="0 0 0" xyz="0 0 0.048"/>
      <geometry>
        <box size="0.04 0.04 0.096"/>
      </geometry>
      <material name="white"/>
    </visual>
    <collision>
      <origin rpy="0 0 0" xyz="0 0 0.048"/>
      <geometry>
        <box size="0.04 0.04 0.096"/>
      </geometry>
    </collision>
  </link>
  <link name="wrist_bracket">
    <inertial>
      <origin rpy="0 0 0" xyz="0 0.052 0"/>
      <mass value="0.00712"/>
      <inertia ixx="0.00000174511" ixy="0.0" ixz="0.0" iyy="0.00000379922" iyz="0.0" izz="0.00000357521"/>
    </inertial>
    <visual>
      <origin rpy="0 0 0" xyz="0 0.052 0"/>
      <geometry>
        <mesh filename="package://mobile_manipulator/meshes/F4.stl" scale="0.001 0.001 0.001"/>
      </geometry>
      <material name="white"/>
    </visual>
    <collision>
      <origin rpy="0 0 0" xyz="0 0.052 0"/>
      <geometry>
        <mesh filename="package://mobile_manipulator/meshes/F4.stl" scale="0.001 0.001 0.001"/>
      </geometry>
    </collision>
  </link>
  <joint name="base_joint" type="fixed">
    <origin rpy="1.57 0 3.14" xyz="0 0.02 0"/>
    <parent link="base_link"/>
    <child link="shoulder_yaw_motor"/>
  </joint>
  <joint name="shoulder_yaw" type="revolute">
    <origin rpy="1.57 0 1.57" xyz="0 0 0.041"/>
    <parent link="shoulder_yaw_motor"/>
    <child link="shoulder_pitch_motor"/>
    <axis xyz="0 1 0"/>
    <limit effort="30" lower="-3.14" upper="3.14" velocity="1.0"/>
  </joint>
  <joint name="shoulder_pitch" type="revolute">
    <origin rpy="0 1.57 1.57" xyz="0 0.0481 0"/>
    <parent link="shoulder_pitch_motor"/>
    <child link="shoulder_bracket"/>
    <axis xyz="1 0 0"/>
    <limit effort="30" lower="-1.57" upper="1.57" velocity="1.0"/>
  </joint>
  <joint name="biceps_start" type="fixed">
    <origin rpy="0 0 3.14" xyz="0 0 0.038"/>
    <parent link="shoulder_bracket"/>
    <child link="biscep"/>
  </joint>
  <joint name="biceps_end" type="fixed">
    <origin rpy="1.57 0 1.57" xyz="0 0 0.096"/>
    <parent link="biscep"/>
    <child link="elbow_motor"/>
  </joint>
  <joint name="elbow_pitch" type="revolute">
    <origin rpy="0 1.57 1.57" xyz="0 0.0481 0"/>
    <parent link="elbow_motor"/>
    <child link="elbow_bracket"/>
    <axis xyz="1 0 0"/>
    <limit effort="30" lower="-1.57" upper="1.57" velocity="1.0"/>
  </joint>
  <joint name="forearm_start" type="fixed">
    <origin rpy="0 0 3.14" xyz="0 0 0.038"/>
    <parent link="elbow_bracket"/>
    <child link="forearm"/>
  </joint>
  <joint name="forearm_end" type="fixed">
    <origin rpy="1.57 0 1.57" xyz="0 0 0.096"/>
    <parent link="forearm"/>
    <child link="wrist_bracket"/>
  </joint>
</robot>
