<?xml version="1.0" encoding="utf-8"?>
<!-- =================================================================================== -->
<!-- |    This document was autogenerated by xacro from shoulder_pitch.xacro           | -->
<!-- |    EDITING THIS FILE BY HAND IS NOT RECOMMENDED                                 | -->
<!-- =================================================================================== -->
<robot name="manipulator">
  <!--0.5624 height to start-->
  <material name="white">
    <color rgba="1 1 1 1"/>
  </material>
  <!-- MACROS -->
  <!-- LINKS -->
  <!-- the trans parameter present here is to toggle distance of current object with respect to previous adjacent object i.e. its parent-->
  <link name="base_link">
    <inertial>
      <origin rpy="0 0 0" xyz="0 0 0.5624"/>
      <mass value="0.00048"/>
      <inertia ixx="0.000050799110" ixy="0.0" ixz="0.0" iyy="0.00002857215" iyz="0.00000051457" izz="0.000043394"/>
    </inertial>
    <visual>
      <origin rpy="0 0 0" xyz="0 0 0.5624"/>
      <geometry>
        <box size="0.04 0.04 0.096"/>
      </geometry>
      <material name="white"/>
    </visual>
    <collision>
      <origin rpy="0 0 0" xyz="0 0 0.5624"/>
      <geometry>
        <box size="0.04 0.04 0.096"/>
      </geometry>
    </collision>
  </link>
  <link name="shoulder_yaw_motor">
    <inertial>
      <origin rpy="0 0 0 " xyz="0 0 0.0205"/>
      <mass value="0.140"/>
      <inertia ixx="0.000050799110" ixy="0.0" ixz="0.0" iyy="0.00002857215" iyz="0.00000051457" izz="0.000043394"/>
    </inertial>
    <visual>
      <origin rpy="0 0 0 " xyz="0 0 0.0205"/>
      <geometry>
        <mesh filename="package://mobile_manipulator/meshes/dynamixel_x64series.stl" scale="0.001 0.001 0.001"/>
      </geometry>
      <material name="white"/>
    </visual>
    <collision>
      <origin rpy="0 0 0" xyz="0 0 0.0205"/>
      <geometry>
        <mesh filename="package://mobile_manipulator/meshes/dynamixel_x64series.stl" scale="0.001 0.001 0.001"/>
      </geometry>
    </collision>
  </link>
  <link name="biscep">
    <inertial>
      <origin rpy="0 0 0" xyz="0 0.023 0.1791"/>
      <mass value="0.53"/>
      <inertia ixx="0.000050799110" ixy="0.0" ixz="0.0" iyy="0.00002857215" iyz="0.00000051457" izz="0.000043394"/>
    </inertial>
    <visual>
      <origin rpy="0 0 0" xyz="0 0.023 0.1791"/>
      <geometry>
        <box size="0.04 0.04 0.3842"/>
      </geometry>
      <material name="white"/>
    </visual>
    <collision>
      <origin rpy="0 0 0" xyz="0 0.023 0.1791"/>
      <geometry>
        <box size="0.04 0.04 0.3842"/>
      </geometry>
    </collision>
  </link>
  <joint name="base_joint" type="fixed">
    <origin rpy="1.57 0 3.14" xyz="0 0.02 0.5624"/>
    <parent link="base_link"/>
    <child link="shoulder_yaw_motor"/>
  </joint>
  <joint name="shoulder_yaw" type="revolute">
    <origin rpy="1.57 0 0" xyz="0 0 0.041"/>
    <parent link="shoulder_yaw_motor"/>
    <child link="biscep"/>
    <axis xyz="0 1 0"/>
    <limit effort="300" lower="-3.14" upper="3.14" velocity="1.0"/>
  </joint>
</robot>
